2024-09-13 18:42:04,571	INFO worker.py:1783 -- Started a local Ray instance.
Traceback (most recent call last):
  File "/home/ishida/magpie/exp/gen_ins.py", line 88, in <module>
    llm = LLM(model=args.model_path, 
  File "/home/ishida/magpie/venv/lib/python3.9/site-packages/vllm/entrypoints/llm.py", line 175, in __init__
    self.llm_engine = LLMEngine.from_engine_args(
  File "/home/ishida/magpie/venv/lib/python3.9/site-packages/vllm/engine/llm_engine.py", line 471, in from_engine_args
    executor_class = cls._get_executor_cls(engine_config)
  File "/home/ishida/magpie/venv/lib/python3.9/site-packages/vllm/engine/llm_engine.py", line 446, in _get_executor_cls
    initialize_ray_cluster(engine_config.parallel_config)
  File "/home/ishida/magpie/venv/lib/python3.9/site-packages/vllm/executor/ray_utils.py", line 261, in initialize_ray_cluster
    raise ValueError(
ValueError: The number of required GPUs exceeds the total number of available GPUs in the placement group.
